<?xml version="1.0"?>

<robot xmlns:xacro="http://www.ros.org/wiki/xacro" >
        
    <link name="base_footprint"/>

    <link name="base_link">
        <visual>
            <geometry>
                <mesh filename="package://bot_description/meshes/carenagem.stl" scale="0.001 0.001 0.001"/>
            </geometry>
            <origin xyz="0 0 0.008" rpy="0 0 1.57"/>
        </visual>
        <collision>
            <geometry>
                <mesh filename="package://bot_description/meshes/carenagem.stl" scale="0.001 0.001 0.001"/>
            </geometry>
            <origin xyz="0 0 0" rpy="0 0 1.57"/>
        </collision>
    
    </link>

    <joint name="base_joint" type="fixed">
        <parent link="base_footprint"/>
        <child link="base_link"/>
        <origin rpy="0 0 0" xyz="0 0 0.033" />
    </joint>

    <!-- WHEELS -->

    <link name="wheel_right_link">
        <inertial>
            <origin xyz="0 0.0085 0" rpy="0 0 0" />
            <mass value="0.0530086090966721" />
            <inertia ixx="1.88176298336665E-05" ixy="-4.8444933029987E-10" ixz="1.88163708851143E-08"
                iyy="3.11510738647764E-05" iyz="-6.93560663069607E-11"
                izz="1.8801969558182E-05" />
        </inertial>
        <visual>
            <origin rpy="1.57 0 0" xyz="0 0.008 0" />
            <geometry>
                <mesh filename="package://bot_description/meshes/wheel_right_link.STL" />
            </geometry>
        </visual>
        <collision>
            <origin xyz="0 0.008 0" rpy="1.57 0 0"/>
            <geometry>
                <sphere radius="0.033"/>
            </geometry>
        </collision>
    </link>
    

    <joint name="wheel_right_joint" type="continuous">
        <parent link="base_link"/>
        <child link="wheel_right_link"/>
        <axis xyz="0 1 0"/>
        <origin rpy="0 0 0" xyz="0 -0.085 0"/>
    </joint>

    <link name="wheel_left_link">
        <inertial>
            <origin xyz="0 -0.0085 0" rpy="0 0 0" />
            <mass value="0.0530086043217644" />
            <inertia ixx="1.8792911368909E-05"  ixy="3.31256392204584E-10" ixz="-1.14082001662767E-08"
               iyy="3.11510738759073E-05" iyz="-3.60499245082192E-10"
               izz="1.88266886146847E-05" />
        </inertial>
        <visual>
            <origin rpy="-1.57 0 0" xyz="0 -0.008 0" />
            <geometry>
                <mesh filename="package://bot_description/meshes/wheel_left_link.STL" />
            </geometry>
        </visual>
        <collision>
            <origin xyz="0 -0.0085 0" rpy="1.57 0 0"/>
            <geometry>
                <sphere radius="0.033"/>
            </geometry>
        </collision>
    </link>

    <joint name="wheel_left_joint" type="continuous">
        <parent link="base_link"/>
        <child link="wheel_left_link"/>
        <axis xyz="0 1 0"/>
        <origin rpy="0 0 0" xyz="0 0.085 0"/>
    </joint>

    <!-- CASTER -->

    <link name="caster_front_link">
        <inertial>
            <origin xyz="3.89968128948481E-07 2.40073004698083E-07 0.00219173397061506" rpy="0 0 0" />
            <mass value="1.44379265037903E-06" />
            <inertia ixx="7.23075276010246E-11" ixy="-6.10956883467859E-16" ixz="2.22849693525031E-15"
               iyy="3.8713793085917E-11"  iyz="2.93909858781952E-15"
               izz="1.00967486676306E-10" />
        </inertial>
        <visual>
            <origin rpy="0 0 0" xyz="0 0 0.005"/>
            <geometry>
                <!--mesh filename="package://bot_description/meshes/caster_front_link.STL"/-->
                <sphere radius="0.02" />
            </geometry>
        </visual>
        <collision>
            <origin xyz="0 0 0" rpy="0 0 0"/>
            <geometry>
                <sphere radius="0.02"/>
            </geometry>
        </collision>
    </link>

    <joint name="caster_front_joint" type="fixed">
        <parent link="base_link"/>
        <child link="caster_front_link"/>
        <origin rpy="0 0 0" xyz="-0.07 0 -0.02" />
    </joint>

    <link name="caster_rear_link">
        <inertial>
            <origin xyz="3.89968128948481E-07 2.40073004698083E-07 0.00219173397061506" rpy="0 0 0" />
            <mass value="1.44379265037903E-06" />
            <inertia ixx="7.23075276010246E-11" ixy="-6.10956883467859E-16" ixz="2.22849693525031E-15"
               iyy="3.8713793085917E-11"  iyz="2.93909858781952E-15"
               izz="1.00967486676306E-10" />
        </inertial>
        <visual>
            <origin rpy="0 0 0" xyz="0 0 0.005"/>
            <geometry>
                <!--mesh filename="package://bot_description/meshes/caster_front_link.STL"/-->
                <sphere radius="0.02" />
            </geometry>
        </visual>
        <collision>
            <origin xyz="0 0 0" rpy="0 0 0"/>
            <geometry>
                <sphere radius="0.02"/>
            </geometry>
        </collision>
    </link>

    <joint name="caster_rear_joint" type="fixed">
        <parent link="base_link"/>
        <child link="caster_rear_link"/>
        <origin rpy="0 0 0" xyz="0.07 0 -0.02" />
    </joint>
       
</robot>
